<?xml version="1.0" encoding="UTF-8"?>
<!-- Generated by org.testng.reporters.JUnitReportReporter -->
<testsuite hostname="k" name="com.cpeoc.appiunTestDemo.test.yy.CopyOfMyFirstTest" tests="6" failures="0" timestamp="25 Oct 2017 02:05:28 GMT" time="0.011" errors="2">
  <testcase name="test004" time="0.003" classname="com.cpeoc.appiunTestDemo.test.yy.CopyOfMyFirstTest"/>
  <testcase name="test006" time="0.002" classname="com.cpeoc.appiunTestDemo.test.yy.CopyOfMyFirstTest">
    <error type="java.lang.AssertionError" message="expected [true] but found [false]">
      <![CDATA[java.lang.AssertionError: expected [true] but found [false]
	at org.testng.Assert.fail(Assert.java:94)
	at org.testng.Assert.failNotEquals(Assert.java:494)
	at org.testng.Assert.assertTrue(Assert.java:42)
	at org.testng.Assert.assertTrue(Assert.java:52)
	at com.cpeoc.appiunTestDemo.test.yy.CopyOfMyFirstTest.test006(CopyOfMyFirstTest.java:24)
	at sun.reflect.NativeMethodAccessorImpl.invoke0(Native Method)
	at sun.reflect.NativeMethodAccessorImpl.invoke(NativeMethodAccessorImpl.java:62)
	at sun.reflect.DelegatingMethodAccessorImpl.invoke(DelegatingMethodAccessorImpl.java:43)
	at java.lang.reflect.Method.invoke(Method.java:498)
	at org.testng.internal.MethodInvocationHelper.invokeMethod(MethodInvocationHelper.java:84)
	at org.testng.internal.Invoker.invokeMethod(Invoker.java:714)
	at org.testng.internal.Invoker.invokeTestMethod(Invoker.java:901)
	at org.testng.internal.Invoker.invokeTestMethods(Invoker.java:1231)
	at org.testng.internal.TestMethodWorker.invokeTestMethods(TestMethodWorker.java:127)
	at org.testng.internal.TestMethodWorker.run(TestMethodWorker.java:111)
	at org.testng.TestRunner.privateRun(TestRunner.java:767)
	at org.testng.TestRunner.run(TestRunner.java:617)
	at org.testng.SuiteRunner.runTest(SuiteRunner.java:335)
	at org.testng.SuiteRunner.access$000(SuiteRunner.java:37)
	at org.testng.SuiteRunner$SuiteWorker.run(SuiteRunner.java:369)
	at org.testng.internal.thread.ThreadUtil$2.call(ThreadUtil.java:64)
	at java.util.concurrent.FutureTask.run(FutureTask.java:266)
	at java.util.concurrent.ThreadPoolExecutor.runWorker(ThreadPoolExecutor.java:1142)
	at java.util.concurrent.ThreadPoolExecutor$Worker.run(ThreadPoolExecutor.java:617)
	at java.lang.Thread.run(Thread.java:748)
]]>
    </error>
  </testcase> <!-- test006 -->
  <testcase name="test005" time="0.000" classname="com.cpeoc.appiunTestDemo.test.yy.CopyOfMyFirstTest"/>
  <testcase name="test006" time="0.002" classname="com.cpeoc.appiunTestDemo.test.yy.CopyOfMyFirstTest">
    <error type="java.lang.AssertionError" message="expected [true] but found [false]">
      <![CDATA[java.lang.AssertionError: expected [true] but found [false]
	at org.testng.Assert.fail(Assert.java:94)
	at org.testng.Assert.failNotEquals(Assert.java:494)
	at org.testng.Assert.assertTrue(Assert.java:42)
	at org.testng.Assert.assertTrue(Assert.java:52)
	at com.cpeoc.appiunTestDemo.test.yy.CopyOfMyFirstTest.test006(CopyOfMyFirstTest.java:24)
	at sun.reflect.NativeMethodAccessorImpl.invoke0(Native Method)
	at sun.reflect.NativeMethodAccessorImpl.invoke(NativeMethodAccessorImpl.java:62)
	at sun.reflect.DelegatingMethodAccessorImpl.invoke(DelegatingMethodAccessorImpl.java:43)
	at java.lang.reflect.Method.invoke(Method.java:498)
	at org.testng.internal.MethodInvocationHelper.invokeMethod(MethodInvocationHelper.java:84)
	at org.testng.internal.Invoker.invokeMethod(Invoker.java:714)
	at org.testng.internal.Invoker.invokeTestMethod(Invoker.java:901)
	at org.testng.internal.Invoker.invokeTestMethods(Invoker.java:1231)
	at org.testng.internal.TestMethodWorker.invokeTestMethods(TestMethodWorker.java:127)
	at org.testng.internal.TestMethodWorker.run(TestMethodWorker.java:111)
	at org.testng.TestRunner.privateRun(TestRunner.java:767)
	at org.testng.TestRunner.run(TestRunner.java:617)
	at org.testng.SuiteRunner.runTest(SuiteRunner.java:335)
	at org.testng.SuiteRunner.access$000(SuiteRunner.java:37)
	at org.testng.SuiteRunner$SuiteWorker.run(SuiteRunner.java:369)
	at org.testng.internal.thread.ThreadUtil$2.call(ThreadUtil.java:64)
	at java.util.concurrent.FutureTask.run(FutureTask.java:266)
	at java.util.concurrent.ThreadPoolExecutor.runWorker(ThreadPoolExecutor.java:1142)
	at java.util.concurrent.ThreadPoolExecutor$Worker.run(ThreadPoolExecutor.java:617)
	at java.lang.Thread.run(Thread.java:748)
]]>
    </error>
  </testcase> <!-- test006 -->
  <testcase name="test005" time="0.000" classname="com.cpeoc.appiunTestDemo.test.yy.CopyOfMyFirstTest"/>
  <testcase name="test004" time="0.004" classname="com.cpeoc.appiunTestDemo.test.yy.CopyOfMyFirstTest"/>
</testsuite> <!-- com.cpeoc.appiunTestDemo.test.yy.CopyOfMyFirstTest -->
